Workbook

Sheet Sheet1_Source
A1: SHORTCUT MMT - SOURCE OF TRUTH
A2: Edit only here | rows: 344 | linked profiles auto-refresh on open
A3: Nhóm | B3: Tiếng Anh | C3: Phím tắt | D3: Tiếng Việt | E3: Key
A4: 🔹 CHUNG (General) | B4: Go To First Selected Line | C4: Ctrl+L | D4: Chuyển tới dòng đầu tiên đã chọn | E4: =CONCATENATE(B4,"§",C4,"§",D4)
A5: 🔹 CHUNG (General) | B5: Go To Next Empty Line | D5: Chuyển tới dòng trống tiếp theo | E5: =CONCATENATE(B5,"§",C5,"§",D5)
A6: 🔹 CHUNG (General) | B6: Merge Selected Lines | C6: Ctrl+Shift+M | D6: Gộp các dòng đã chọn | E6: =CONCATENATE(B6,"§",C6,"§",D6)
A7: 🔹 CHUNG (General) | B7: Merge Selected Lines And Auto Break | D7: Gộp các dòng đã chọn và tự ngắt dòng | E7: =CONCATENATE(B7,"§",C7,"§",D7)
A8: 🔹 CHUNG (General) | B8: Merge Selected Lines And Unbreak | C8: Alt+K | D8: Gộp các dòng đã chọn và không ngắt dòng | E8: =CONCATENATE(B8,"§",C8,"§",D8)
A9: 🔹 CHUNG (General) | B9: Merge Selected Lines And Unbreak CJK | D9: Gộp các dòng đã chọn và không ngắt dòng (CJK) | E9: =CONCATENATE(B9,"§",C9,"§",D9)
A10: 🔹 CHUNG (General) | B10: Merge Selected Lines Only First Text | D10: Gộp các dòng đã chọn (chỉ văn bản đầu) | E10: =CONCATENATE(B10,"§",C10,"§",D10)
A11: 🔹 CHUNG (General) | B11: Merge Selected Lines Bilingual | D11: Gộp các dòng đã chọn (song ngữ) | E11: =CONCATENATE(B11,"§",C11,"§",D11)
A12: 🔹 CHUNG (General) | B12: Merge With Previous Bilingual | D12: Gộp với dòng trước (song ngữ) | E12: =CONCATENATE(B12,"§",C12,"§",D12)
A13: 🔹 CHUNG (General) | B13: Merge With Next Bilingual | D13: Gộp với dòng sau (song ngữ) | E13: =CONCATENATE(B13,"§",C13,"§",D13)
A14: 🔹 CHUNG (General) | B14: Merge With Next | D14: Gộp với dòng sau | E14: =CONCATENATE(B14,"§",C14,"§",D14)
A15: 🔹 CHUNG (General) | B15: Merge With Previous | C15: Ctrl+Shift+PageUp | D15: Gộp với dòng trước | E15: =CONCATENATE(B15,"§",C15,"§",D15)
A16: 🔹 CHUNG (General) | B16: Merge With Previous And Unbreak | C16: Ctrl+M | D16: Gộp với dòng trước và không ngắt dòng | E16: =CONCATENATE(B16,"§",C16,"§",D16)
A17: 🔹 CHUNG (General) | B17: Merge With Next And Unbreak | D17: Gộp với dòng sau và không ngắt dòng | E17: =CONCATENATE(B17,"§",C17,"§",D17)
A18: 🔹 CHUNG (General) | B18: Merge With Previous And Break | D18: Gộp với dòng trước và ngắt dòng | E18: =CONCATENATE(B18,"§",C18,"§",D18)
A19: 🔹 CHUNG (General) | B19: Merge With Next And Break | D19: Gộp với dòng sau và ngắt dòng | E19: =CONCATENATE(B19,"§",C19,"§",D19)
A20: 🔹 CHUNG (General) | B20: Toggle Translation Mode | C20: Ctrl+Shift+O | D20: Bật/Tắt chế độ dịch | E20: =CONCATENATE(B20,"§",C20,"§",D20)
A21: 🔹 CHUNG (General) | B21: Switch Original And Translation | D21: Hoán đổi bản gốc và bản dịch | E21: =CONCATENATE(B21,"§",C21,"§",D21)
A22: 🔹 CHUNG (General) | B22: Switch Original And Translation Text Boxes | C22: Ctrl+Alt+O | D22: Hoán đổi hộp văn bản gốc và dịch | E22: =CONCATENATE(B22,"§",C22,"§",D22)
A23: 🔹 CHUNG (General) | B23: Layout Choose | C23: Alt+Shift+D0 | D23: Chọn bố cục | E23: =CONCATENATE(B23,"§",C23,"§",D23)
A24: 🔹 CHUNG (General) | B24: Layout Choose 1-12 | D24: Chọn bố cục 1-12 | E24: =CONCATENATE(B24,"§",C24,"§",D24)
A25: 🔹 CHUNG (General) | B25: Merge Original And Translation | C25: Ctrl+Alt+Shift+M | D25: Gộp bản gốc và bản dịch | E25: =CONCATENATE(B25,"§",C25,"§",D25)
A26: 🔹 CHUNG (General) | B26: Go To Next Subtitle | C26: Shift+Return | D26: Chuyển tới phụ đề tiếp theo | E26: =CONCATENATE(B26,"§",C26,"§",D26)
A27: 🔹 CHUNG (General) | B27: Go To Next Subtitle Play Translate | C27: Alt+Down | D27: Đi tới phụ đề tiếp theo, phát và dịch | E27: =CONCATENATE(B27,"§",C27,"§",D27)
A28: 🔹 CHUNG (General) | B28: Go To Next Subtitle Cursor At End | D28: Chuyển tới phụ đề tiếp theo (con trỏ ở cuối) | E28: =CONCATENATE(B28,"§",C28,"§",D28)
A29: 🔹 CHUNG (General) | B29: Go To Prev Subtitle | D29: Chuyển tới phụ đề trước | E29: =CONCATENATE(B29,"§",C29,"§",D29)
A30: 🔹 CHUNG (General) | B30: Go To Prev Subtitle Play Translate | C30: Alt+Up | D30: Đi tới phụ đề trước, phát và dịch | E30: =CONCATENATE(B30,"§",C30,"§",D30)
A31: 🔹 CHUNG (General) | B31: Go To End Of Current Subtitle | D31: Chuyển tới cuối phụ đề hiện tại | E31: =CONCATENATE(B31,"§",C31,"§",D31)
A32: 🔹 CHUNG (General) | B32: Go To Start Of Current Subtitle | D32: Chuyển tới đầu phụ đề hiện tại | E32: =CONCATENATE(B32,"§",C32,"§",D32)
A33: 🔹 CHUNG (General) | B33: Go To Previous Subtitle And Focus Video | D33: Đi tới phụ đề trước và đưa tiêu điểm vào video | E33: =CONCATENATE(B33,"§",C33,"§",D33)
A34: 🔹 CHUNG (General) | B34: Go To Next Subtitle And Focus Video | D34: Đi tới phụ đề sau và đưa tiêu điểm vào video | E34: =CONCATENATE(B34,"§",C34,"§",D34)
A35: 🔹 CHUNG (General) | B35: Go To Previous Subtitle And Focus Waveform | D35: Đi tới phụ đề trước và đưa tiêu điểm vào dạng sóng | E35: =CONCATENATE(B35,"§",C35,"§",D35)
A36: 🔹 CHUNG (General) | B36: Go To Next Subtitle And Focus Waveform | D36: Đi tới phụ đề sau và đưa tiêu điểm vào dạng sóng | E36: =CONCATENATE(B36,"§",C36,"§",D36)
A37: 🔹 CHUNG (General) | B37: Go To Prev Subtitle And Play | C37: Ctrl+Up | D37: Đi tới phụ đề trước và phát | E37: =CONCATENATE(B37,"§",C37,"§",D37)
A38: 🔹 CHUNG (General) | B38: Go To Next Subtitle And Play | C38: Ctrl+Down | D38: Đi tới phụ đề sau và phát | E38: =CONCATENATE(B38,"§",C38,"§",D38)
A39: 🔹 CHUNG (General) | B39: Auto Calc Current Duration | D39: Tự tính thời lượng hiện tại | E39: =CONCATENATE(B39,"§",C39,"§",D39)
A40: 🔹 CHUNG (General) | B40: Auto Calc Current Duration By Optimal Reading Speed | D40: Tự tính thời lượng theo tốc độ đọc tối ưu | E40: =CONCATENATE(B40,"§",C40,"§",D40)
...

Sheet 01 - New Subtitle
A1: 01 - New Subtitle
A2: Linked to Sheet1_Source | rows: 100
A3: Nhóm | B3: Tiếng Anh | C3: Phím tắt | D3: Tiếng Việt | E3: Key
A4: ='Sheet1_Source'!A4 | B4: ='Sheet1_Source'!B4 | C4: ='Sheet1_Source'!C4 | D4: ='Sheet1_Source'!D4 | E4: 4
A5: ='Sheet1_Source'!A5 | B5: ='Sheet1_Source'!B5 | C5: ='Sheet1_Source'!C5 | D5: ='Sheet1_Source'!D5 | E5: 5
A6: ='Sheet1_Source'!A7 | B6: ='Sheet1_Source'!B7 | C6: ='Sheet1_Source'!C7 | D6: ='Sheet1_Source'!D7 | E6: 7
A7: ='Sheet1_Source'!A10 | B7: ='Sheet1_Source'!B10 | C7: ='Sheet1_Source'!C10 | D7: ='Sheet1_Source'!D10 | E7: 10
A8: ='Sheet1_Source'!A39 | B8: ='Sheet1_Source'!B39 | C8: ='Sheet1_Source'!C39 | D8: ='Sheet1_Source'!D39 | E8: 39
A9: ='Sheet1_Source'!A40 | B9: ='Sheet1_Source'!B40 | C9: ='Sheet1_Source'!C40 | D9: ='Sheet1_Source'!D40 | E9: 40
A10: ='Sheet1_Source'!A41 | B10: ='Sheet1_Source'!B41 | C10: ='Sheet1_Source'!C41 | D10: ='Sheet1_Source'!D41 | E10: 41
A11: ='Sheet1_Source'!A42 | B11: ='Sheet1_Source'!B42 | C11: ='Sheet1_Source'!C42 | D11: ='Sheet1_Source'!D42 | E11: 42
A12: ='Sheet1_Source'!A226 | B12: ='Sheet1_Source'!B226 | C12: ='Sheet1_Source'!C226 | D12: ='Sheet1_Source'!D226 | E12: 226
A13: ='Sheet1_Source'!A227 | B13: ='Sheet1_Source'!B227 | C13: ='Sheet1_Source'!C227 | D13: ='Sheet1_Source'!D227 | E13: 227
A14: ='Sheet1_Source'!A228 | B14: ='Sheet1_Source'!B228 | C14: ='Sheet1_Source'!C228 | D14: ='Sheet1_Source'!D228 | E14: 228
A15: ='Sheet1_Source'!A229 | B15: ='Sheet1_Source'!B229 | C15: ='Sheet1_Source'!C229 | D15: ='Sheet1_Source'!D229 | E15: 229
A16: ='Sheet1_Source'!A242 | B16: ='Sheet1_Source'!B242 | C16: ='Sheet1_Source'!C242 | D16: ='Sheet1_Source'!D242 | E16: 242
A17: ='Sheet1_Source'!A243 | B17: ='Sheet1_Source'!B243 | C17: ='Sheet1_Source'!C243 | D17: ='Sheet1_Source'!D243 | E17: 243
A18: ='Sheet1_Source'!A244 | B18: ='Sheet1_Source'!B244 | C18: ='Sheet1_Source'!C244 | D18: ='Sheet1_Source'!D244 | E18: 244
A19: ='Sheet1_Source'!A245 | B19: ='Sheet1_Source'!B245 | C19: ='Sheet1_Source'!C245 | D19: ='Sheet1_Source'!D245 | E19: 245
A20: ='Sheet1_Source'!A246 | B20: ='Sheet1_Source'!B246 | C20: ='Sheet1_Source'!C246 | D20: ='Sheet1_Source'!D246 | E20: 246
A21: ='Sheet1_Source'!A247 | B21: ='Sheet1_Source'!B247 | C21: ='Sheet1_Source'!C247 | D21: ='Sheet1_Source'!D247 | E21: 247
A22: ='Sheet1_Source'!A250 | B22: ='Sheet1_Source'!B250 | C22: ='Sheet1_Source'!C250 | D22: ='Sheet1_Source'!D250 | E22: 250
A23: ='Sheet1_Source'!A67 | B23: ='Sheet1_Source'!B67 | C23: ='Sheet1_Source'!C67 | D23: ='Sheet1_Source'!D67 | E23: 67
A24: ='Sheet1_Source'!A73 | B24: ='Sheet1_Source'!B73 | C24: ='Sheet1_Source'!C73 | D24: ='Sheet1_Source'!D73 | E24: 73
A25: ='Sheet1_Source'!A126 | B25: ='Sheet1_Source'!B126 | C25: ='Sheet1_Source'!C126 | D25: ='Sheet1_Source'!D126 | E25: 126
A26: ='Sheet1_Source'!A127 | B26: ='Sheet1_Source'!B127 | C26: ='Sheet1_Source'!C127 | D26: ='Sheet1_Source'!D127 | E26: 127
A27: ='Sheet1_Source'!A128 | B27: ='Sheet1_Source'!B128 | C27: ='Sheet1_Source'!C128 | D27: ='Sheet1_Source'!D128 | E27: 128
A28: ='Sheet1_Source'!A129 | B28: ='Sheet1_Source'!B129 | C28: ='Sheet1_Source'!C129 | D28: ='Sheet1_Source'!D129 | E28: 129
A29: ='Sheet1_Source'!A133 | B29: ='Sheet1_Source'!B133 | C29: ='Sheet1_Source'!C133 | D29: ='Sheet1_Source'!D133 | E29: 133
A30: ='Sheet1_Source'!A134 | B30: ='Sheet1_Source'!B134 | C30: ='Sheet1_Source'!C134 | D30: ='Sheet1_Source'!D134 | E30: 134
A31: ='Sheet1_Source'!A135 | B31: ='Sheet1_Source'!B135 | C31: ='Sheet1_Source'!C135 | D31: ='Sheet1_Source'!D135 | E31: 135
A32: ='Sheet1_Source'!A136 | B32: ='Sheet1_Source'!B136 | C32: ='Sheet1_Source'!C136 | D32: ='Sheet1_Source'!D136 | E32: 136
A33: ='Sheet1_Source'!A137 | B33: ='Sheet1_Source'!B137 | C33: ='Sheet1_Source'!C137 | D33: ='Sheet1_Source'!D137 | E33: 137
A34: ='Sheet1_Source'!A138 | B34: ='Sheet1_Source'!B138 | C34: ='Sheet1_Source'!C138 | D34: ='Sheet1_Source'!D138 | E34: 138
A35: ='Sheet1_Source'!A139 | B35: ='Sheet1_Source'!B139 | C35: ='Sheet1_Source'!C139 | D35: ='Sheet1_Source'!D139 | E35: 139
A36: ='Sheet1_Source'!A140 | B36: ='Sheet1_Source'!B140 | C36: ='Sheet1_Source'!C140 | D36: ='Sheet1_Source'!D140 | E36: 140
A37: ='Sheet1_Source'!A141 | B37: ='Sheet1_Source'!B141 | C37: ='Sheet1_Source'!C141 | D37: ='Sheet1_Source'!D141 | E37: 141
A38: ='Sheet1_Source'!A142 | B38: ='Sheet1_Source'!B142 | C38: ='Sheet1_Source'!C142 | D38: ='Sheet1_Source'!D142 | E38: 142
A39: ='Sheet1_Source'!A143 | B39: ='Sheet1_Source'!B143 | C39: ='Sheet1_Source'!C143 | D39: ='Sheet1_Source'!D143 | E39: 143
A40: ='Sheet1_Source'!A144 | B40: ='Sheet1_Source'!B144 | C40: ='Sheet1_Source'!C144 | D40: ='Sheet1_Source'!D144 | E40: 144
...

Sheet 02 - Translate Existing
A1: 02 - Translate Existing
A2: Linked to Sheet1_Source | rows: 68
A3: Nhóm | B3: Tiếng Anh | C3: Phím tắt | D3: Tiếng Việt | E3: Key
A4: ='Sheet1_Source'!A6 | B4: ='Sheet1_Source'!B6 | C4: ='Sheet1_Source'!C6 | D4: ='Sheet1_Source'!D6 | E4: 6
A5: ='Sheet1_Source'!A8 | B5: ='Sheet1_Source'!B8 | C5: ='Sheet1_Source'!C8 | D5: ='Sheet1_Source'!D8 | E5: 8
A6: ='Sheet1_Source'!A9 | B6: ='Sheet1_Source'!B9 | C6: ='Sheet1_Source'!C9 | D6: ='Sheet1_Source'!D9 | E6: 9
A7: ='Sheet1_Source'!A11 | B7: ='Sheet1_Source'!B11 | C7: ='Sheet1_Source'!C11 | D7: ='Sheet1_Source'!D11 | E7: 11
A8: ='Sheet1_Source'!A12 | B8: ='Sheet1_Source'!B12 | C8: ='Sheet1_Source'!C12 | D8: ='Sheet1_Source'!D12 | E8: 12
A9: ='Sheet1_Source'!A13 | B9: ='Sheet1_Source'!B13 | C9: ='Sheet1_Source'!C13 | D9: ='Sheet1_Source'!D13 | E9: 13
A10: ='Sheet1_Source'!A14 | B10: ='Sheet1_Source'!B14 | C10: ='Sheet1_Source'!C14 | D10: ='Sheet1_Source'!D14 | E10: 14
A11: ='Sheet1_Source'!A15 | B11: ='Sheet1_Source'!B15 | C11: ='Sheet1_Source'!C15 | D11: ='Sheet1_Source'!D15 | E11: 15
A12: ='Sheet1_Source'!A16 | B12: ='Sheet1_Source'!B16 | C12: ='Sheet1_Source'!C16 | D12: ='Sheet1_Source'!D16 | E12: 16
A13: ='Sheet1_Source'!A17 | B13: ='Sheet1_Source'!B17 | C13: ='Sheet1_Source'!C17 | D13: ='Sheet1_Source'!D17 | E13: 17
A14: ='Sheet1_Source'!A20 | B14: ='Sheet1_Source'!B20 | C14: ='Sheet1_Source'!C20 | D14: ='Sheet1_Source'!D20 | E14: 20
A15: ='Sheet1_Source'!A21 | B15: ='Sheet1_Source'!B21 | C15: ='Sheet1_Source'!C21 | D15: ='Sheet1_Source'!D21 | E15: 21
A16: ='Sheet1_Source'!A22 | B16: ='Sheet1_Source'!B22 | C16: ='Sheet1_Source'!C22 | D16: ='Sheet1_Source'!D22 | E16: 22
A17: ='Sheet1_Source'!A25 | B17: ='Sheet1_Source'!B25 | C17: ='Sheet1_Source'!C25 | D17: ='Sheet1_Source'!D25 | E17: 25
A18: ='Sheet1_Source'!A26 | B18: ='Sheet1_Source'!B26 | C18: ='Sheet1_Source'!C26 | D18: ='Sheet1_Source'!D26 | E18: 26
A19: ='Sheet1_Source'!A27 | B19: ='Sheet1_Source'!B27 | C19: ='Sheet1_Source'!C27 | D19: ='Sheet1_Source'!D27 | E19: 27
A20: ='Sheet1_Source'!A28 | B20: ='Sheet1_Source'!B28 | C20: ='Sheet1_Source'!C28 | D20: ='Sheet1_Source'!D28 | E20: 28
A21: ='Sheet1_Source'!A29 | B21: ='Sheet1_Source'!B29 | C21: ='Sheet1_Source'!C29 | D21: ='Sheet1_Source'!D29 | E21: 29
A22: ='Sheet1_Source'!A30 | B22: ='Sheet1_Source'!B30 | C22: ='Sheet1_Source'!C30 | D22: ='Sheet1_Source'!D30 | E22: 30
A23: ='Sheet1_Source'!A31 | B23: ='Sheet1_Source'!B31 | C23: ='Sheet1_Source'!C31 | D23: ='Sheet1_Source'!D31 | E23: 31
A24: ='Sheet1_Source'!A32 | B24: ='Sheet1_Source'!B32 | C24: ='Sheet1_Source'!C32 | D24: ='Sheet1_Source'!D32 | E24: 32
A25: ='Sheet1_Source'!A33 | B25: ='Sheet1_Source'!B33 | C25: ='Sheet1_Source'!C33 | D25: ='Sheet1_Source'!D33 | E25: 33
A26: ='Sheet1_Source'!A34 | B26: ='Sheet1_Source'!B34 | C26: ='Sheet1_Source'!C34 | D26: ='Sheet1_Source'!D34 | E26: 34
A27: ='Sheet1_Source'!A37 | B27: ='Sheet1_Source'!B37 | C27: ='Sheet1_Source'!C37 | D27: ='Sheet1_Source'!D37 | E27: 37
A28: ='Sheet1_Source'!A38 | B28: ='Sheet1_Source'!B38 | C28: ='Sheet1_Source'!C38 | D28: ='Sheet1_Source'!D38 | E28: 38
A29: ='Sheet1_Source'!A335 | B29: ='Sheet1_Source'!B335 | C29: ='Sheet1_Source'!C335 | D29: ='Sheet1_Source'!D335 | E29: 335
A30: ='Sheet1_Source'!A336 | B30: ='Sheet1_Source'!B336 | C30: ='Sheet1_Source'!C336 | D30: ='Sheet1_Source'!D336 | E30: 336
A31: ='Sheet1_Source'!A337 | B31: ='Sheet1_Source'!B337 | C31: ='Sheet1_Source'!C337 | D31: ='Sheet1_Source'!D337 | E31: 337
A32: ='Sheet1_Source'!A338 | B32: ='Sheet1_Source'!B338 | C32: ='Sheet1_Source'!C338 | D32: ='Sheet1_Source'!D338 | E32: 338
A33: ='Sheet1_Source'!A339 | B33: ='Sheet1_Source'!B339 | C33: ='Sheet1_Source'!C339 | D33: ='Sheet1_Source'!D339 | E33: 339
A34: ='Sheet1_Source'!A130 | B34: ='Sheet1_Source'!B130 | C34: ='Sheet1_Source'!C130 | D34: ='Sheet1_Source'!D130 | E34: 130
A35: ='Sheet1_Source'!A131 | B35: ='Sheet1_Source'!B131 | C35: ='Sheet1_Source'!C131 | D35: ='Sheet1_Source'!D131 | E35: 131
A36: ='Sheet1_Source'!A132 | B36: ='Sheet1_Source'!B132 | C36: ='Sheet1_Source'!C132 | D36: ='Sheet1_Source'!D132 | E36: 132
A37: ='Sheet1_Source'!A153 | B37: ='Sheet1_Source'!B153 | C37: ='Sheet1_Source'!C153 | D37: ='Sheet1_Source'!D153 | E37: 153
A38: ='Sheet1_Source'!A154 | B38: ='Sheet1_Source'!B154 | C38: ='Sheet1_Source'!C154 | D38: ='Sheet1_Source'!D154 | E38: 154
A39: ='Sheet1_Source'!A155 | B39: ='Sheet1_Source'!B155 | C39: ='Sheet1_Source'!C155 | D39: ='Sheet1_Source'!D155 | E39: 155
A40: ='Sheet1_Source'!A156 | B40: ='Sheet1_Source'!B156 | C40: ='Sheet1_Source'!C156 | D40: ='Sheet1_Source'!D156 | E40: 156
...

Sheet 03 - Edit Translated
A1: 03 - Edit Translated
A2: Linked to Sheet1_Source | rows: 142
A3: Nhóm | B3: Tiếng Anh | C3: Phím tắt | D3: Tiếng Việt | E3: Key
A4: ='Sheet1_Source'!A80 | B4: ='Sheet1_Source'!B80 | C4: ='Sheet1_Source'!C80 | D4: ='Sheet1_Source'!D80 | E4: 80
A5: ='Sheet1_Source'!A81 | B5: ='Sheet1_Source'!B81 | C5: ='Sheet1_Source'!C81 | D5: ='Sheet1_Source'!D81 | E5: 81
A6: ='Sheet1_Source'!A82 | B6: ='Sheet1_Source'!B82 | C6: ='Sheet1_Source'!C82 | D6: ='Sheet1_Source'!D82 | E6: 82
A7: ='Sheet1_Source'!A316 | B7: ='Sheet1_Source'!B316 | C7: ='Sheet1_Source'!C316 | D7: ='Sheet1_Source'!D316 | E7: 316
A8: ='Sheet1_Source'!A317 | B8: ='Sheet1_Source'!B317 | C8: ='Sheet1_Source'!C317 | D8: ='Sheet1_Source'!D317 | E8: 317
A9: ='Sheet1_Source'!A321 | B9: ='Sheet1_Source'!B321 | C9: ='Sheet1_Source'!C321 | D9: ='Sheet1_Source'!D321 | E9: 321
A10: ='Sheet1_Source'!A322 | B10: ='Sheet1_Source'!B322 | C10: ='Sheet1_Source'!C322 | D10: ='Sheet1_Source'!D322 | E10: 322
A11: ='Sheet1_Source'!A323 | B11: ='Sheet1_Source'!B323 | C11: ='Sheet1_Source'!C323 | D11: ='Sheet1_Source'!D323 | E11: 323
A12: ='Sheet1_Source'!A324 | B12: ='Sheet1_Source'!B324 | C12: ='Sheet1_Source'!C324 | D12: ='Sheet1_Source'!D324 | E12: 324
A13: ='Sheet1_Source'!A325 | B13: ='Sheet1_Source'!B325 | C13: ='Sheet1_Source'!C325 | D13: ='Sheet1_Source'!D325 | E13: 325
A14: ='Sheet1_Source'!A326 | B14: ='Sheet1_Source'!B326 | C14: ='Sheet1_Source'!C326 | D14: ='Sheet1_Source'!D326 | E14: 326
A15: ='Sheet1_Source'!A327 | B15: ='Sheet1_Source'!B327 | C15: ='Sheet1_Source'!C327 | D15: ='Sheet1_Source'!D327 | E15: 327
A16: ='Sheet1_Source'!A334 | B16: ='Sheet1_Source'!B334 | C16: ='Sheet1_Source'!C334 | D16: ='Sheet1_Source'!D334 | E16: 334
A17: ='Sheet1_Source'!A90 | B17: ='Sheet1_Source'!B90 | C17: ='Sheet1_Source'!C90 | D17: ='Sheet1_Source'!D90 | E17: 90
A18: ='Sheet1_Source'!A91 | B18: ='Sheet1_Source'!B91 | C18: ='Sheet1_Source'!C91 | D18: ='Sheet1_Source'!D91 | E18: 91
A19: ='Sheet1_Source'!A92 | B19: ='Sheet1_Source'!B92 | C19: ='Sheet1_Source'!C92 | D19: ='Sheet1_Source'!D92 | E19: 92
A20: ='Sheet1_Source'!A93 | B20: ='Sheet1_Source'!B93 | C20: ='Sheet1_Source'!C93 | D20: ='Sheet1_Source'!D93 | E20: 93
A21: ='Sheet1_Source'!A94 | B21: ='Sheet1_Source'!B94 | C21: ='Sheet1_Source'!C94 | D21: ='Sheet1_Source'!D94 | E21: 94
A22: ='Sheet1_Source'!A95 | B22: ='Sheet1_Source'!B95 | C22: ='Sheet1_Source'!C95 | D22: ='Sheet1_Source'!D95 | E22: 95
A23: ='Sheet1_Source'!A96 | B23: ='Sheet1_Source'!B96 | C23: ='Sheet1_Source'!C96 | D23: ='Sheet1_Source'!D96 | E23: 96
A24: ='Sheet1_Source'!A97 | B24: ='Sheet1_Source'!B97 | C24: ='Sheet1_Source'!C97 | D24: ='Sheet1_Source'!D97 | E24: 97
A25: ='Sheet1_Source'!A98 | B25: ='Sheet1_Source'!B98 | C25: ='Sheet1_Source'!C98 | D25: ='Sheet1_Source'!D98 | E25: 98
A26: ='Sheet1_Source'!A99 | B26: ='Sheet1_Source'!B99 | C26: ='Sheet1_Source'!C99 | D26: ='Sheet1_Source'!D99 | E26: 99
A27: ='Sheet1_Source'!A100 | B27: ='Sheet1_Source'!B100 | C27: ='Sheet1_Source'!C100 | D27: ='Sheet1_Source'!D100 | E27: 100
A28: ='Sheet1_Source'!A101 | B28: ='Sheet1_Source'!B101 | C28: ='Sheet1_Source'!C101 | D28: ='Sheet1_Source'!D101 | E28: 101
... A30: ='Sheet1_Source'!A103 | B30: ='Sheet1_Source'!B103 | C30: ='Sheet1_Source'!C103 | D30: ='Sheet1_Source'!D103 | E30: 103
A31: ='Sheet1_Source'!A109 | B31: ='Sheet1_Source'!B109 | C31: ='Sheet1_Source'!C109 | D31: ='Sheet1_Source'!D109 | E31: 109
A32: ='Sheet1_Source'!A110 | B32: ='Sheet1_Source'!B110 | C32: ='Sheet1_Source'!C110 | D32: ='Sheet1_Source'!D110 | E32: 110
A33: ='Sheet1_Source'!A111 | B33: ='Sheet1_Source'!B111 | C33: ='Sheet1_Source'!C111 | D33: ='Sheet1_Source'!D111 | E33: 111
A34: ='Sheet1_Source'!A113 | B34: ='Sheet1_Source'!B113 | C34: ='Sheet1_Source'!C113 | D34: ='Sheet1_Source'!D113 | E34: 113
A35: ='Sheet1_Source'!A115 | B35: ='Sheet1_Source'!B115 | C35: ='Sheet1_Source'!C115 | D35: ='Sheet1_Source'!D115 | E35: 115
A36: ='Sheet1_Source'!A116 | B36: ='Sheet1_Source'!B116 | C36: ='Sheet1_Source'!C116 | D36: ='Sheet1_Source'!D116 | E36: 116
A37: ='Sheet1_Source'!A117 | B37: ='Sheet1_Source'!B117 | C37: ='Sheet1_Source'!C117 | D37: ='Sheet1_Source'!D117 | E37: 117
A38: ='Sheet1_Source'!A118 | B38: ='Sheet1_Source'!B118 | C38: ='Sheet1_Source'!C118 | D38: ='Sheet1_Source'!D118 | E38: 118
A39: ='Sheet1_Source'!A120 | B39: ='Sheet1_Source'!B120 | C39: ='Sheet1_Source'!C120 | D39: ='Sheet1_Source'!D120 | E39: 120
A40: ='Sheet1_Source'!A121 | B40: ='Sheet1_Source'!B121 | C40: ='Sheet1_Source'!C121 | D40: ='Sheet1_Source'!D121 | E40: 121
A41: ='Sheet1_Source'!A122 | B41: ='Sheet1_Source'!B122 | C41: ='Sheet1_Source'!C122 | D41: ='Sheet1_Source'!D122 | E41: 122
...

Sheet 04 - Quick Checker
A1: 04 - Quick Checker
A2: Linked to Sheet1_Source | rows: 34
A3: Nhóm | B3: Tiếng Anh | C3: Phím tắt | D3: Tiếng Việt | E3: Key
A4: ='Sheet1_Source'!A106 | B4: ='Sheet1_Source'!B106 | C4: ='Sheet1_Source'!C106 | D4: ='Sheet1_Source'!D106 | E4: 106
A5: ='Sheet1_Source'!A107 | B5: ='Sheet1_Source'!B107 | C5: ='Sheet1_Source'!C107 | D5: ='Sheet1_Source'!D107 | E5: 107
A6: ='Sheet1_Source'!A175 | B6: ='Sheet1_Source'!B175 | C6: ='Sheet1_Source'!C175 | D6: ='Sheet1_Source'!D175 | E6: 175
A7: ='Sheet1_Source'!A176 | B7: ='Sheet1_Source'!B176 | C7: ='Sheet1_Source'!C176 | D7: ='Sheet1_Source'!D176 | E7: 176
A8: ='Sheet1_Source'!A177 | B8: ='Sheet1_Source'!B177 | C8: ='Sheet1_Source'!C177 | D8: ='Sheet1_Source'!D177 | E8: 177
A9: ='Sheet1_Source'!A76 | B9: ='Sheet1_Source'!B76 | C9: ='Sheet1_Source'!C76 | D9: ='Sheet1_Source'!D76 | E9: 76
A10: ='Sheet1_Source'!A77 | B10: ='Sheet1_Source'!B77 | C10: ='Sheet1_Source'!C77 | D10: ='Sheet1_Source'!D77 | E10: 77
A11: ='Sheet1_Source'!A83 | B11: ='Sheet1_Source'!B83 | C11: ='Sheet1_Source'!C83 | D11: ='Sheet1_Source'!D83 | E11: 83
A12: ='Sheet1_Source'!A84 | B12: ='Sheet1_Source'!B84 | C12: ='Sheet1_Source'!C84 | D12: ='Sheet1_Source'!D84 | E12: 84
A13: ='Sheet1_Source'!A85 | B13: ='Sheet1_Source'!B85 | C13: ='Sheet1_Source'!C85 | D13: ='Sheet1_Source'!D85 | E13: 85
A14: ='Sheet1_Source'!A86 | B14: ='Sheet1_Source'!B86 | C14: ='Sheet1_Source'!C86 | D14: ='Sheet1_Source'!D86 | E14: 86
A15: ='Sheet1_Source'!A87 | B15: ='Sheet1_Source'!B87 | C15: ='Sheet1_Source'!C87 | D15: ='Sheet1_Source'!D87 | E15: 87
A16: ='Sheet1_Source'!A88 | B16: ='Sheet1_Source'!B88 | C16: ='Sheet1_Source'!C88 | D16: ='Sheet1_Source'!D88 | E16: 88
A17: ='Sheet1_Source'!A199 | B17: ='Sheet1_Source'!B199 | C17: ='Sheet1_Source'!C199 | D17: ='Sheet1_Source'!D199 | E17: 199
A18: ='Sheet1_Source'!A210 | B18: ='Sheet1_Source'!B210 | C18: ='Sheet1_Source'!C210 | D18: ='Sheet1_Source'!D210 | E18: 210
A19: ='Sheet1_Source'!A211 | B19: ='Sheet1_Source'!B211 | C19: ='Sheet1_Source'!C211 | D19: ='Sheet1_Source'!D211 | E19: 211
A20: ='Sheet1_Source'!A212 | B20: ='Sheet1_Source'!B212 | C20: ='Sheet1_Source'!C212 | D20: ='Sheet1_Source'!D212 | E20: 212
A21: ='Sheet1_Source'!A213 | B21: ='Sheet1_Source'!B213 | C21: ='Sheet1_Source'!C213 | D21: ='Sheet1_Source'!D213 | E21: 213
A22: ='Sheet1_Source'!A214 | B22: ='Sheet1_Source'!B214 | C22: ='Sheet1_Source'!C214 | D22: ='Sheet1_Source'!D214 | E22: 214
A23: ='Sheet1_Source'!A215 | B23: ='Sheet1_Source'!B215 | C23: ='Sheet1_Source'!C215 | D23: ='Sheet1_Source'!D215 | E23: 215
A24: ='Sheet1_Source'!A216 | B24: ='Sheet1_Source'!B216 | C24: ='Sheet1_Source'!C216 | D24: ='Sheet1_Source'!D216 | E24: 216
A25: ='Sheet1_Source'!A217 | B25: ='Sheet1_Source'!B217 | C25: ='Sheet1_Source'!C217 | D25: ='Sheet1_Source'!D217 | E25: 217
A26: ='Sheet1_Source'!A218 | B26: ='Sheet1_Source'!B218 | C26: ='Sheet1_Source'!C218 | D26: ='Sheet1_Source'!D218 | E26: 218
A27: ='Sheet1_Source'!A219 | B27: ='Sheet1_Source'!B219 | C27: ='Sheet1_Source'!C219 | D27: ='Sheet1_Source'!D219 | E27: 219
A28: ='Sheet1_Source'!A220 | B28: ='Sheet1_Source'!B220 | C28: ='Sheet1_Source'!C220 | D28: ='Sheet1_Source'!D220 | E28: 220
A29: ='Sheet1_Source'!A221 | B29: ='Sheet1_Source'!B221 | C29: ='Sheet1_Source'!C221 | D29: ='Sheet1_Source'!D221 | E29: 221
... A33: ='Sheet1_Source'!A225 | B33: ='Sheet1_Source'!B225 | C33: ='Sheet1_Source'!C225 | D33: ='Sheet1_Source'!D225 | E33: 225
A34: ='Sheet1_Source'!A165 | B34: ='Sheet1_Source'!B165 | C34: ='Sheet1_Source'!C165 | D34: ='Sheet1_Source'!D165 | E34: 165
A35: ='Sheet1_Source'!A166 | B35: ='Sheet1_Source'!B166 | C35: ='Sheet1_Source'!C166 | D35: ='Sheet1_Source'!D166 | E35: 166
A36: ='Sheet1_Source'!A167 | B36: ='Sheet1_Source'!B167 | C36: ='Sheet1_Source'!C167 | D36: ='Sheet1_Source'!D167 | E36: 167
A37: ='Sheet1_Source'!A168 | B37: ='Sheet1_Source'!B168 | C37: ='Sheet1_Source'!C168 | D37: ='Sheet1_Source'!D168 | E37: 168
